Attempt 1 at connecting failed: OSError: [WinError 1231] Сетевая папка недоступна. За информацией о разрешении проблем в сети обратитесь к справочной системе Windows
Attempt 2 at connecting failed: OSError: [WinError 1231] Сетевая папка недоступна. За информацией о разрешении проблем в сети обратитесь к справочной системе Windows
Attempt 3 at connecting failed: OSError: [WinError 1231] Сетевая папка недоступна. За информацией о разрешении проблем в сети обратитесь к справочной системе Windows
Attempt 4 at connecting failed: OSError: [WinError 1231] Сетевая папка недоступна. За информацией о разрешении проблем в сети обратитесь к справочной системе Windows
Attempt 5 at connecting failed: OSError: [WinError 1231] Сетевая папка недоступна. За информацией о разрешении проблем в сети обратитесь к справочной системе Windows
Attempt 6 at connecting failed: OSError: [WinError 1231] Сетевая папка недоступна. За информацией о разрешении проблем в сети обратитесь к справочной системе Windows
Traceback (most recent call last):
  File "F:\study_with_me\study_tracker.py", line 672, in <module>
    asyncio.run(main())
    ~~~~~~~~~~~^^^^^^^^
  File "C:\Users\hp\AppData\Local\Programs\Python\Python313\Lib\asyncio\runners.py", line 195, in run
    return runner.run(main)
           ~~~~~~~~~~^^^^^^
  File "C:\Users\hp\AppData\Local\Programs\Python\Python313\Lib\asyncio\runners.py", line 118, in run
    return self._loop.run_until_complete(task)
           ~~~~~~~~~~~~~~~~~~~~~~~~~~~~~^^^^^^
  File "C:\Users\hp\AppData\Local\Programs\Python\Python313\Lib\asyncio\base_events.py", line 725, in run_until_complete
    return future.result()
           ~~~~~~~~~~~~~^^
  File "F:\study_with_me\study_tracker.py", line 580, in main
    await client.connect()
  File "F:\study_with_me\.venv\Lib\site-packages\telethon\client\telegrambaseclient.py", line 552, in connect
    if not await self._sender.connect(self._connection(
           ^^^^^^^^^^^^^^^^^^^^^^^^^^^^^^^^^^^^^^^^^^^^
    ...<6 lines>...
    )):
    ^^
  File "F:\study_with_me\.venv\Lib\site-packages\telethon\network\mtprotosender.py", line 134, in connect
    await self._connect()
  File "F:\study_with_me\.venv\Lib\site-packages\telethon\network\mtprotosender.py", line 260, in _connect
    raise ConnectionError('Connection to Telegram failed {} time(s)'.format(self._retries))
ConnectionError: Connection to Telegram failed 5 time(s)
